Traceback (most recent call last):
  File "/clusterFS/home/student/kopp13/miniconda3/envs/tensorflow/lib/python3.5/site-packages/tensorflow/python/pywrap_tensorflow.py", line 58, in <module>
    from tensorflow.python.pywrap_tensorflow_internal import *
  File "/clusterFS/home/student/kopp13/miniconda3/envs/tensorflow/lib/python3.5/site-packages/tensorflow/python/pywrap_tensorflow_internal.py", line 28, in <module>
    _pywrap_tensorflow_internal = swig_import_helper()
  File "/clusterFS/home/student/kopp13/miniconda3/envs/tensorflow/lib/python3.5/site-packages/tensorflow/python/pywrap_tensorflow_internal.py", line 24, in swig_import_helper
    _mod = imp.load_module('_pywrap_tensorflow_internal', fp, pathname, description)
  File "/clusterFS/home/student/kopp13/miniconda3/envs/tensorflow/lib/python3.5/imp.py", line 243, in load_module
    return load_dynamic(name, filename, file)
  File "/clusterFS/home/student/kopp13/miniconda3/envs/tensorflow/lib/python3.5/imp.py", line 343, in load_dynamic
    return _load(spec)
ImportError: libcublas.so.9.0: cannot open shared object file: No such file or directory

During handling of the above exception, another exception occurred:

Traceback (most recent call last):
  File "../experiments/noise_exp.py", line 7, in <module>
    from src.run_experiment import run_experiment
  File "../src/run_experiment.py", line 1, in <module>
    import tensorflow as tf
  File "/clusterFS/home/student/kopp13/miniconda3/envs/tensorflow/lib/python3.5/site-packages/tensorflow/__init__.py", line 24, in <module>
    from tensorflow.python import *
  File "/clusterFS/home/student/kopp13/miniconda3/envs/tensorflow/lib/python3.5/site-packages/tensorflow/python/__init__.py", line 49, in <module>
    from tensorflow.python import pywrap_tensorflow
  File "/clusterFS/home/student/kopp13/miniconda3/envs/tensorflow/lib/python3.5/site-packages/tensorflow/python/pywrap_tensorflow.py", line 74, in <module>
    raise ImportError(msg)
ImportError: Traceback (most recent call last):
  File "/clusterFS/home/student/kopp13/miniconda3/envs/tensorflow/lib/python3.5/site-packages/tensorflow/python/pywrap_tensorflow.py", line 58, in <module>
    from tensorflow.python.pywrap_tensorflow_internal import *
  File "/clusterFS/home/student/kopp13/miniconda3/envs/tensorflow/lib/python3.5/site-packages/tensorflow/python/pywrap_tensorflow_internal.py", line 28, in <module>
    _pywrap_tensorflow_internal = swig_import_helper()
  File "/clusterFS/home/student/kopp13/miniconda3/envs/tensorflow/lib/python3.5/site-packages/tensorflow/python/pywrap_tensorflow_internal.py", line 24, in swig_import_helper
    _mod = imp.load_module('_pywrap_tensorflow_internal', fp, pathname, description)
  File "/clusterFS/home/student/kopp13/miniconda3/envs/tensorflow/lib/python3.5/imp.py", line 243, in load_module
    return load_dynamic(name, filename, file)
  File "/clusterFS/home/student/kopp13/miniconda3/envs/tensorflow/lib/python3.5/imp.py", line 343, in load_dynamic
    return _load(spec)
ImportError: libcublas.so.9.0: cannot open shared object file: No such file or directory


Failed to load the native TensorFlow runtime.

See https://www.tensorflow.org/install/install_sources#common_installation_problems

for some common reasons and solutions.  Include the entire stack trace
above this error message when asking for help.
